test_delete_queue (__main__.TestExercice) ... FAIL
test_delete_stack (__main__.TestExercice) ... FAIL
test_reverse (__main__.TestExercice) ... FAIL
test_sort_queue (__main__.TestExercice) ... FAIL
test_sort_stack (__main__.TestExercice) ... FAIL
test_string_and_structs (__main__.TestExercice) ... ERROR

======================================================================
ERROR: test_string_and_structs (__main__.TestExercice)
----------------------------------------------------------------------
Traceback (most recent call last):
  File "test_exercice.py", line 91, in test_string_and_structs
    fifo.put_many("Yeet")
TypeError: put_many() missing 1 required positional argument: 'items'

======================================================================
FAIL: test_delete_queue (__main__.TestExercice)
----------------------------------------------------------------------
Traceback (most recent call last):
  File "test_exercice.py", line 53, in test_delete_queue
    'Mauvaise reponse'
AssertionError: [] != [1, 2, 3, 4, 5, 6, 7, 8, 9, 10, 11, 12, 13, 14, 15, 16, 17, 18, 19] : Mauvaise reponse

======================================================================
FAIL: test_delete_stack (__main__.TestExercice)
----------------------------------------------------------------------
Traceback (most recent call last):
  File "test_exercice.py", line 38, in test_delete_stack
    'Mauvaise reponse'
AssertionError: [] != [0, 1, 2, 3, 4, 5, 6, 7, 8, 9, 10, 11, 12, 13, 14, 15, 16, 17, 18] : Mauvaise reponse

======================================================================
FAIL: test_reverse (__main__.TestExercice)
----------------------------------------------------------------------
Traceback (most recent call last):
  File "test_exercice.py", line 23, in test_reverse
    'Mauvaise reponse'
AssertionError: First sequence is not a list: None

======================================================================
FAIL: test_sort_queue (__main__.TestExercice)
----------------------------------------------------------------------
Traceback (most recent call last):
  File "test_exercice.py", line 83, in test_sort_queue
    'Mauvaise reponse'
AssertionError: [] != [53, 202, 229, 266, 380, 413, 422, 489, 49[52 chars] 937] : Mauvaise reponse

======================================================================
FAIL: test_sort_stack (__main__.TestExercice)
----------------------------------------------------------------------
Traceback (most recent call last):
  File "test_exercice.py", line 68, in test_sort_stack
    'Mauvaise reponse'
AssertionError: [] != [21, 30, 137, 159, 187, 199, 256, 260, 266[52 chars]1000] : Mauvaise reponse

----------------------------------------------------------------------
Ran 6 tests in 0.001s

FAILED (failures=5, errors=1)
